<mujoco model="X30">
  <compiler angle="radian" meshdir="../meshes/"/>

  <asset>
    <mesh name="torso" content_type="model/stl" file="torso.STL"/>
    <mesh name="hip" content_type="model/stl" file="hip.STL"/>
    <mesh name="thigh" content_type="model/stl" file="thigh.STL"/>
    <mesh name="shank" content_type="model/stl" file="shank.STL"/>
    <mesh name="hip1" content_type="model/stl" file="hip.STL" scale="1 -1 1"/>
    <mesh name="thigh1" content_type="model/stl" file="thigh.STL" scale="1 -1 1"/>
    <mesh name="hip2" content_type="model/stl" file="hip.STL" scale="-1 1 1"/>
    <mesh name="hip3" content_type="model/stl" file="hip.STL" scale="-1 -1 1"/>
    <texture name="texplane" type="2d" builtin="checker" rgb1=".2 .3 .4" rgb2=".1 0.15 0.2"
                 width="512" height="512"/>
        <!--        <material name='geom' texture="texgeom" texuniform="true"/>-->
    <material name='MatPlane' reflectance='0.3' texture="texplane" texrepeat="1 1" texuniform="true"/>
  </asset>

  <worldbody>
    <light directional="true" pos="-0.5 0.5 3" dir="0 0 -1"/>
        <!--        <geom name="floor" pos="0 0 0" rgba="0.8 0.9 0.8 1" size="40 40 40" type="plane"/>-->
    <geom name='floor' pos='0 0 0' size='100 100 .125' type='plane' material="MatPlane" condim='3'
              friction="1 0.01 0.01" group="0"/>
    <body name="TORSO" pos="0 0 0.226" quat="1 0 0 0">
      <freejoint name="floating_base"/>
      <site name="imu_site" pos="0 0 0" size="0.005" rgba="1 0 0 1"/>
      <inertial pos="0 0 0" quat="0.000872206 0.707353 0.000314919 0.70686" mass="30.7" diaginertia="0.757268 0.597627 0.364306"/>
      <geom type="mesh" contype="0" conaffinity="0" group="1" density="0" mesh="torso"/>
      <geom size="0.23 0.13 0.09" type="box"/>
      <body name="FL_HIP" pos="0.291 0.08 0">
        <inertial pos="-0.0018591 -0.011377 0.00027039" quat="0.492096 0.500552 0.506945 0.500295" mass="1.43" diaginertia="0.00267847 0.00159184 0.00140649"/>
        <joint name="FL_HipX_joint" pos="0 0 0" axis="-1 0 0" range="-0.323 0.585" actuatorfrcrange="-84 84"/>
        <geom type="mesh" contype="0" conaffinity="0" group="1" density="0" mesh="hip"/>
        <body name="FL_THIGH" pos="0 0.11675 0">
          <inertial pos="-0.0087581 -0.023554 -0.055162" quat="0.724056 0.0298504 0.00499363 0.689077" mass="4.0809" diaginertia="0.0164227 0.0126096 0.00608011"/>
          <joint name="FL_HipY_joint" pos="0 0 0" axis="0 -1 0" range="-2.967 0.262" actuatorfrcrange="-84 84"/>
          <geom type="mesh" contype="0" conaffinity="0" group="1" density="0" mesh="thigh"/>
          <geom size="0.04 0.125" pos="-0.02 0 -0.13" type="cylinder"/>
          <body name="FL_SHANK" pos="0 0 -0.3">
            <inertial pos="0.014851 2.0685e-05 -0.12283" quat="0.707008 -0.0139742 -0.0136862 0.706935" mass="0.71386" diaginertia="0.0096272 0.00931754 0.000401781"/>
            <joint name="FL_Knee_joint" pos="0 0 0" axis="0 -1 0" range="0.349 2.531" actuatorfrcrange="-150 150"/>
            <geom type="mesh" contype="0" conaffinity="0" group="1" density="0" mesh="shank"/>
            <geom size="0.025 0.05" pos="0.02 0 -0.046" quat="0.980067 0 -0.198669 0" type="cylinder"/>
            <geom size="0.015 0.05" pos="0.045 0 -0.1421" type="cylinder"/>
            <geom size="0.015 0.04" pos="0.02 0 -0.246" quat="0.980067 0 0.198669 0" type="cylinder"/>
            <body name="FL_FOOT" pos="0 0 -0.31">
              <inertial pos="0 0 0" mass="0.06" diaginertia="1e-12 1e-12 1e-12"/>
              <geom size="0.036"/>
            </body>
          </body>
        </body>
      </body>
      <body name="FR_HIP" pos="0.291 -0.08 0">
        <inertial pos="-0.0018591 0.011377 -2.7675e-05" quat="0.507783 0.499436 0.488975 0.503611" mass="1.43" diaginertia="0.00267852 0.00159185 0.00140643"/>
        <joint name="FR_HipX_joint" pos="0 0 0" axis="-1 0 0" range="-0.585 0.323" actuatorfrcrange="-84 84"/>
        <geom type="mesh" contype="0" conaffinity="0" group="1" density="0" mesh="hip1"/>
        <body name="FR_THIGH" pos="0 -0.11675 0">
          <inertial pos="-0.0087433 0.023551 -0.055154" quat="0.688998 0.00499198 0.0298429 0.724132" mass="4.0809" diaginertia="0.0164227 0.0126095 0.00608033"/>
          <joint name="FR_HipY_joint" pos="0 0 0" axis="0 -1 0" range="-2.967 0.262" actuatorfrcrange="-84 84"/>
          <geom type="mesh" contype="0" conaffinity="0" group="1" density="0" mesh="thigh1"/>
          <geom size="0.04 0.125" pos="-0.02 0 -0.13" type="cylinder"/>
          <body name="FR_SHANK" pos="0 0 -0.3">
            <inertial pos="0.014851 2.0687e-05 -0.12283" quat="0.707008 -0.0139742 -0.0136862 0.706935" mass="0.71386" diaginertia="0.0096272 0.00931754 0.000401781"/>
            <joint name="FR_Knee_joint" pos="0 0 0" axis="0 -1 0" range="0.349 2.531" actuatorfrcrange="-150 150"/>
            <geom type="mesh" contype="0" conaffinity="0" group="1" density="0" mesh="shank"/>
            <geom size="0.025 0.05" pos="0.02 0 -0.046" quat="0.980067 0 -0.198669 0" type="cylinder"/>
            <geom size="0.015 0.05" pos="0.045 0 -0.1421" type="cylinder"/>
            <geom size="0.015 0.04" pos="0.02 0 -0.246" quat="0.980067 0 0.198669 0" type="cylinder"/>
            <body name="FR_FOOT" pos="0 0 -0.31">
              <inertial pos="0 0 0" mass="0.06" diaginertia="1e-12 1e-12 1e-12"/>
              <geom size="0.036"/>
            </body>
          </body>
        </body>
      </body>
      <body name="HL_HIP" pos="-0.291 0.08 0">
        <inertial pos="0.0018591 -0.011377 -2.7675e-05" quat="0.499436 0.507783 0.503611 0.488975" mass="1.43" diaginertia="0.00267852 0.00159185 0.00140643"/>
        <joint name="HL_HipX_joint" pos="0 0 0" axis="-1 0 0" range="-0.323 0.585" actuatorfrcrange="-84 84"/>
        <geom type="mesh" contype="0" conaffinity="0" group="1" density="0" mesh="hip2"/>
        <body name="HL_THIGH" pos="0 0.11675 0">
          <inertial pos="-0.0087581 -0.023554 -0.055162" quat="0.724056 0.0298504 0.00499363 0.689077" mass="4.0809" diaginertia="0.0164227 0.0126096 0.00608011"/>
          <joint name="HL_HipY_joint" pos="0 0 0" axis="0 -1 0" range="-2.967 0.262" actuatorfrcrange="-84 84"/>
          <geom type="mesh" contype="0" conaffinity="0" group="1" density="0" mesh="thigh"/>
          <geom size="0.04 0.125" pos="-0.02 0 -0.13" type="cylinder"/>
          <body name="HL_SHANK" pos="0 0 -0.3">
            <inertial pos="0.014851 2.0679e-05 -0.12283" quat="0.707008 -0.0139742 -0.0136862 0.706935" mass="0.71386" diaginertia="0.0096272 0.00931754 0.000401781"/>
            <joint name="HL_Knee_joint" pos="0 0 0" axis="0 -1 0" range="0.349 2.531" actuatorfrcrange="-150 150"/>
            <geom type="mesh" contype="0" conaffinity="0" group="1" density="0" mesh="shank"/>
            <geom size="0.025 0.05" pos="0.02 0 -0.046" quat="0.980067 0 -0.198669 0" type="cylinder"/>
            <geom size="0.015 0.05" pos="0.045 0 -0.1421" type="cylinder"/>
            <geom size="0.015 0.04" pos="0.02 0 -0.246" quat="0.980067 0 0.198669 0" type="cylinder"/>
            <body name="HL_FOOT" pos="0 0 -0.31">
              <inertial pos="0 0 0" mass="0.06" diaginertia="1e-12 1e-12 1e-12"/>
              <geom size="0.036"/>
            </body>
          </body>
        </body>
      </body>
      <body name="HR_HIP" pos="-0.291 -0.08 0">
        <inertial pos="0.0018591 0.011377 0.00027039" quat="0.500552 0.492096 0.500295 0.506945" mass="1.43" diaginertia="0.00267847 0.00159184 0.00140649"/>
        <joint name="HR_HipX_joint" pos="0 0 0" axis="-1 0 0" range="-0.585 0.323" actuatorfrcrange="-84 84"/>
        <geom type="mesh" contype="0" conaffinity="0" group="1" density="0" mesh="hip3"/>
        <body name="HR_THIGH" pos="0 -0.11675 0">
          <inertial pos="-0.0087433 0.023551 -0.055154" quat="0.688998 0.00499198 0.0298429 0.724132" mass="4.0809" diaginertia="0.0164227 0.0126095 0.00608033"/>
          <joint name="HR_HipY_joint" pos="0 0 0" axis="0 -1 0" range="-2.967 0.262" actuatorfrcrange="-84 84"/>
          <geom type="mesh" contype="0" conaffinity="0" group="1" density="0" mesh="thigh1"/>
          <geom size="0.04 0.125" pos="-0.02 0 -0.13" type="cylinder"/>
          <body name="HR_SHANK" pos="0 0 -0.3">
            <inertial pos="0.014851 2.0679e-05 -0.12283" quat="0.707008 -0.0139742 -0.0136862 0.706935" mass="0.71386" diaginertia="0.0096272 0.00931754 0.000401781"/>
            <joint name="HR_Knee_joint" pos="0 0 0" axis="0 -1 0" range="0.349 2.531" actuatorfrcrange="-150 150"/>
            <geom type="mesh" contype="0" conaffinity="0" group="1" density="0" mesh="shank"/>
            <geom size="0.025 0.05" pos="0.02 0 -0.046" quat="0.980067 0 -0.198669 0" type="cylinder"/>
            <geom size="0.015 0.05" pos="0.045 0 -0.1421" type="cylinder"/>
            <geom size="0.015 0.04" pos="0.02 0 -0.246" quat="0.980067 0 0.198669 0" type="cylinder"/>
            <body name="HR_FOOT" pos="0 0 -0.31">
              <inertial pos="0 0 0" mass="0.06" diaginertia="1e-12 1e-12 1e-12"/>
              <geom size="0.036"/>
            </body>
          </body>
        </body>
      </body>
    </body>
  </worldbody>
  <actuator>
    <motor name="FL_HipX_joint_ctrl" joint="FL_HipX_joint" gear="1" ctrlrange="-84 84"/>
    <motor name="FL_HipY_joint_ctrl" joint="FL_HipY_joint" gear="1" ctrlrange="-84 84"/>
    <motor name="FL_Knee_joint_ctrl" joint="FL_Knee_joint" gear="1" ctrlrange="-150 150"/>
    <motor name="FR_HipX_joint_ctrl" joint="FR_HipX_joint" gear="1" ctrlrange="-84 84"/>
    <motor name="FR_HipY_joint_ctrl" joint="FR_HipY_joint" gear="1" ctrlrange="-84 84"/>
    <motor name="FR_Knee_joint_ctrl" joint="FR_Knee_joint" gear="1" ctrlrange="-150 150"/>
    <motor name="HL_HipX_joint_ctrl" joint="HL_HipX_joint" gear="1" ctrlrange="-84 84"/>
    <motor name="HL_HipY_joint_ctrl" joint="HL_HipY_joint" gear="1" ctrlrange="-84 84"/>
    <motor name="HL_Knee_joint_ctrl" joint="HL_Knee_joint" gear="1" ctrlrange="-150 150"/>
    <motor name="HR_HipX_joint_ctrl" joint="HR_HipX_joint" gear="1" ctrlrange="-84 84"/>
    <motor name="HR_HipY_joint_ctrl" joint="HR_HipY_joint" gear="1" ctrlrange="-84 84"/>
    <motor name="HR_Knee_joint_ctrl" joint="HR_Knee_joint" gear="1" ctrlrange="-150 150"/>
  </actuator>
  <sensor>
    <accelerometer name="imu_acc" site="imu_site"/>
    <gyro name="imu_gyro" site="imu_site"/>
  </sensor>
</mujoco>
