<?xml version="1.0" encoding="utf-8"?>
<!-- This URDF was automatically created by SolidWorks to URDF Exporter! Originally created by Stephen Brawner (brawner@gmail.com) 
     Commit Version: 1.6.0-4-g7f85cfe  Build Version: 1.6.7995.38578
     For more information, please see http://wiki.ros.org/sw_urdf_exporter -->
<robot
  name="QuadrupedRobot（2026） V1.2-URDF-20260508-V3">
  <link
    name="base_link">
    <inertial>
      <origin
        xyz="5.0191E-11 4.7017E-09 2.0969E-11"
        rpy="0 0 0" />
      <mass
        value="30" />
      <inertia
        ixx="0.2720939"
        ixy="1.147E-08"
        ixz="7.3979E-10"
        iyy="0.6040536"
        iyz="8.6954E-09"
        izz="0.7274273" />
    </inertial>
    <visual>
      <origin
        xyz="0 0 0"
        rpy="0 0 0" />
      <geometry>
        <mesh
          filename="../meshes/base_link.STL" />
      </geometry>
      <material
        name="">
        <color
          rgba="1 1 1 1" />
      </material>
    </visual>
    <collision>
      <origin
        xyz="0 0 0"
        rpy="0 0 0" />
      <geometry>
        <mesh
          filename="../meshes/base_link.STL" />
      </geometry>
    </collision>
  </link>
  <link
    name="FL_hip_Link">
    <inertial>
      <origin
        xyz="-0.0064702 -0.0031168 -1.8861E-09"
        rpy="0 0 0" />
      <mass
        value="2.5" />
      <inertia
        ixx="0.004546"
        ixy="-3.65E-05"
        ixz="4.5559E-09"
        iyy="0.0072194"
        iyz="-1.0818E-08"
        izz="0.0050078" />
    </inertial>
    <visual>
      <origin
        xyz="0 0 0"
        rpy="0 0 0" />
      <geometry>
        <mesh
          filename="../meshes/FL_hip_Link.STL" />
      </geometry>
      <material
        name="">
        <color
          rgba="1 1 1 1" />
      </material>
    </visual>
    <collision>
      <origin
        xyz="0 0 0"
        rpy="0 0 0" />
      <geometry>
        <mesh
          filename="../meshes/FL_hip_Link.STL" />
      </geometry>
    </collision>
  </link>
  <joint
    name="FL_hip_Joint"
    type="revolute">
    <origin
      xyz="0.31 0.08 0"
      rpy="0 0 0" />
    <parent
      link="base_link" />
    <child
      link="FL_hip_Link" />
    <axis
      xyz="1 0 0" />
    <limit
      lower="-0.7854"
      upper="0.7854"
      effort="75"
      velocity="13.96" />
  </joint>
  <link
    name="FL_thigh_Link">
    <inertial>
      <origin
        xyz="-0.013506 -0.013585 -0.076918"
        rpy="0 0 0" />
      <mass
        value="3.6" />
      <inertia
        ixx="0.047254"
        ixy="-0.0006776"
        ixz="0.0050935"
        iyy="0.048528"
        iyz="-0.003829"
        izz="0.0074044" />
    </inertial>
    <visual>
      <origin
        xyz="0 0 0"
        rpy="0 0 0" />
      <geometry>
        <mesh
          filename="../meshes/FL_thigh_Link.STL" />
      </geometry>
      <material
        name="">
        <color
          rgba="1 1 1 1" />
      </material>
    </visual>
    <collision>
      <origin
        xyz="0 0 0"
        rpy="0 0 0" />
      <geometry>
        <mesh
          filename="../meshes/FL_thigh_Link.STL" />
      </geometry>
    </collision>
  </link>
  <joint
    name="FL_thigh_Joint"
    type="revolute">
    <origin
      xyz="0 0.125 0"
      rpy="0 0 0" />
    <parent
      link="FL_hip_Link" />
    <child
      link="FL_thigh_Link" />
    <axis
      xyz="0 -1 0" />
    <limit
      lower="-4.1538"
      upper="1.012"
      effort="120"
      velocity="8.72" />
  </joint>
  <link
    name="FL_calf_Link">
    <inertial>
      <origin
        xyz="0.01548 5.1235E-08 -0.16117"
        rpy="0 0 0" />
      <mass
        value="1.2" />
      <inertia
        ixx="0.017699"
        ixy="2.717E-10"
        ixz="-0.0011852"
        iyy="0.018059"
        iyz="-6.8945E-09"
        izz="0.0006172" />
    </inertial>
    <visual>
      <origin
        xyz="0 0 0"
        rpy="0 0 0" />
      <geometry>
        <mesh
          filename="../meshes/FL_calf_Link.STL" />
      </geometry>
      <material
        name="">
        <color
          rgba="1 1 1 1" />
      </material>
    </visual>
    <collision>
      <origin
        xyz="0 0 0"
        rpy="0 0 0" />
      <geometry>
        <mesh
          filename="../meshes/FL_calf_Link.STL" />
      </geometry>
    </collision>
  </link>
  <joint
    name="FL_calf_Joint"
    type="revolute">
    <origin
      xyz="0 0 -0.35"
      rpy="0 0 0" />
    <parent
      link="FL_thigh_Link" />
    <child
      link="FL_calf_Link" />
    <axis
      xyz="0 -1 0" />
    <limit
      lower="0.61086"
      upper="2.7925"
      effort="120"
      velocity="8.72" />
  </joint>
  <link
    name="FL_foot_Link">
    <inertial>
      <origin
        xyz="-0.0062191 -2.5813E-15 -0.011423"
        rpy="0 0 0" />
      <mass
        value="0.2" />
      <inertia
        ixx="7.7E-05"
        ixy="2.2617E-10"
        ixz="-1.97E-05"
        iyy="9.6E-05"
        iyz="-5.7823E-10"
        izz="0.0001024" />
    </inertial>
    <visual>
      <origin
        xyz="0 0 0"
        rpy="0 0 0" />
      <geometry>
        <mesh
          filename="../meshes/FL_foot_Link.STL" />
      </geometry>
      <material
        name="">
        <color
          rgba="1 1 1 1" />
      </material>
    </visual>
    <collision>
      <origin
        xyz="0 0 0"
        rpy="0 0 0" />
      <geometry>
        <mesh
          filename="../meshes/FL_foot_Link.STL" />
      </geometry>
    </collision>
  </link>
  <joint
    name="FL_foot_Joint"
    type="fixed">
    <origin
      xyz="0 0 -0.35"
      rpy="0 0 0" />
    <parent
      link="FL_calf_Link" />
    <child
      link="FL_foot_Link" />
    <axis
      xyz="0 0 0" />
  </joint>
  <link
    name="FR_hip_Link">
    <inertial>
      <origin
        xyz="-0.0064702 0.0031168 1.8861E-09"
        rpy="0 0 0" />
      <mass
        value="2.5" />
      <inertia
        ixx="0.0045464"
        ixy="3.65E-05"
        ixz="-4.5559E-09"
        iyy="0.0072194"
        iyz="-1.0818E-08"
        izz="0.0050078" />
    </inertial>
    <visual>
      <origin
        xyz="0 0 0"
        rpy="0 0 0" />
      <geometry>
        <mesh
          filename="../meshes/FR_hip_Link.STL" />
      </geometry>
      <material
        name="">
        <color
          rgba="1 1 1 1" />
      </material>
    </visual>
    <collision>
      <origin
        xyz="0 0 0"
        rpy="0 0 0" />
      <geometry>
        <mesh
          filename="../meshes/FR_hip_Link.STL" />
      </geometry>
    </collision>
  </link>
  <joint
    name="FR_hip_Joint"
    type="revolute">
    <origin
      xyz="0.31 -0.08 0"
      rpy="0 0 0" />
    <parent
      link="base_link" />
    <child
      link="FR_hip_Link" />
    <axis
      xyz="1 0 0" />
    <limit
      lower="-0.7854"
      upper="0.7854"
      effort="75"
      velocity="13.96" />
  </joint>
  <link
    name="FR_thigh_Link">
    <inertial>
      <origin
        xyz="-0.013505 0.013599 -0.077042"
        rpy="0 0 0" />
      <mass
        value="3.6" />
      <inertia
        ixx="0.0472449"
        ixy="0.000678"
        ixz="0.0051024"
        iyy="0.0485268"
        iyz="0.0038394"
        izz="0.0074105" />
    </inertial>
    <visual>
      <origin
        xyz="0 0 0"
        rpy="0 0 0" />
      <geometry>
        <mesh
          filename="../meshes/FR_thigh_Link.STL" />
      </geometry>
      <material
        name="">
        <color
          rgba="1 1 1 1" />
      </material>
    </visual>
    <collision>
      <origin
        xyz="0 0 0"
        rpy="0 0 0" />
      <geometry>
        <mesh
          filename="../meshes/FR_thigh_Link.STL" />
      </geometry>
    </collision>
  </link>
  <joint
    name="FR_thigh_Joint"
    type="revolute">
    <origin
      xyz="0 -0.125 0"
      rpy="0 0 0" />
    <parent
      link="FR_hip_Link" />
    <child
      link="FR_thigh_Link" />
    <axis
      xyz="0 1 0" />
    <limit
      lower="-1.012"
      upper="4.1538"
      effort="120"
      velocity="8.72" />
  </joint>
  <link
    name="FR_calf_Link">
    <inertial>
      <origin
        xyz="0.01548 5.1235E-08 -0.16117"
        rpy="0 0 0" />
      <mass
        value="1.2" />
      <inertia
        ixx="0.0176987"
        ixy="2.717E-10"
        ixz="-0.0011852"
        iyy="0.0180589"
        iyz="-6.8945E-09"
        izz="0.0006172" />
    </inertial>
    <visual>
      <origin
        xyz="0 0 0"
        rpy="0 0 0" />
      <geometry>
        <mesh
          filename="../meshes/FR_calf_Link.STL" />
      </geometry>
      <material
        name="">
        <color
          rgba="1 1 1 1" />
      </material>
    </visual>
    <collision>
      <origin
        xyz="0 0 0"
        rpy="0 0 0" />
      <geometry>
        <mesh
          filename="../meshes/FR_calf_Link.STL" />
      </geometry>
    </collision>
  </link>
  <joint
    name="FR_calf_Joint"
    type="revolute">
    <origin
      xyz="0 0 -0.35"
      rpy="0 0 0" />
    <parent
      link="FR_thigh_Link" />
    <child
      link="FR_calf_Link" />
    <axis
      xyz="0 -1 0" />
    <limit
      lower="0.61086"
      upper="2.7925"
      effort="120"
      velocity="8.72" />
  </joint>
  <link
    name="FR_foot_Link">
    <inertial>
      <origin
        xyz="-0.0062191 -2.498E-15 -0.011423"
        rpy="0 0 0" />
      <mass
        value="0.2" />
      <inertia
        ixx="7.7E-05"
        ixy="2.2617E-10"
        ixz="-1.97E-05"
        iyy="9.6E-05"
        iyz="-5.7823E-10"
        izz="0.0001024" />
    </inertial>
    <visual>
      <origin
        xyz="0 0 0"
        rpy="0 0 0" />
      <geometry>
        <mesh
          filename="../meshes/FR_foot_Link.STL" />
      </geometry>
      <material
        name="">
        <color
          rgba="1 1 1 1" />
      </material>
    </visual>
    <collision>
      <origin
        xyz="0 0 0"
        rpy="0 0 0" />
      <geometry>
        <mesh
          filename="../meshes/FR_foot_Link.STL" />
      </geometry>
    </collision>
  </link>
  <joint
    name="FR_foot_Joint"
    type="fixed">
    <origin
      xyz="0 0 -0.35"
      rpy="0 0 0" />
    <parent
      link="FR_calf_Link" />
    <child
      link="FR_foot_Link" />
    <axis
      xyz="0 0 0" />
  </joint>
  <link
    name="RL_hip_Link">
    <inertial>
      <origin
        xyz="0.0064702 -0.0031168 1.8861E-09"
        rpy="0 0 0" />
      <mass
        value="2.5" />
      <inertia
        ixx="0.0045464"
        ixy="3.65E-05"
        ixz="4.5559E-09"
        iyy="0.0072194"
        iyz="1.0818E-08"
        izz="0.0050078" />
    </inertial>
    <visual>
      <origin
        xyz="0 0 0"
        rpy="0 0 0" />
      <geometry>
        <mesh
          filename="../meshes/RL_hip_Link.STL" />
      </geometry>
      <material
        name="">
        <color
          rgba="1 1 1 1" />
      </material>
    </visual>
    <collision>
      <origin
        xyz="0 0 0"
        rpy="0 0 0" />
      <geometry>
        <mesh
          filename="../meshes/RL_hip_Link.STL" />
      </geometry>
    </collision>
  </link>
  <joint
    name="RL_hip_Joint"
    type="revolute">
    <origin
      xyz="-0.31 0.08 0"
      rpy="0 0 0" />
    <parent
      link="base_link" />
    <child
      link="RL_hip_Link" />
    <axis
      xyz="-1 0 0" />
    <limit
      lower="-0.7854"
      upper="0.7854"
      effort="75"
      velocity="13.96" />
  </joint>
  <link
    name="RL_thigh_Link">
    <inertial>
      <origin
        xyz="-0.013506 -0.013585 -0.076918"
        rpy="0 0 0" />
      <mass
        value="3.6" />
      <inertia
        ixx="0.047254"
        ixy="-0.0006776"
        ixz="0.0050935"
        iyy="0.048528"
        iyz="-0.003829"
        izz="0.0074044" />
    </inertial>
    <visual>
      <origin
        xyz="0 0 0"
        rpy="0 0 0" />
      <geometry>
        <mesh
          filename="../meshes/RL_thigh_Link.STL" />
      </geometry>
      <material
        name="">
        <color
          rgba="1 1 1 1" />
      </material>
    </visual>
    <collision>
      <origin
        xyz="0 0 0"
        rpy="0 0 0" />
      <geometry>
        <mesh
          filename="../meshes/RL_thigh_Link.STL" />
      </geometry>
    </collision>
  </link>
  <joint
    name="RL_thigh_Joint"
    type="revolute">
    <origin
      xyz="0 0.125 0"
      rpy="0 0 0" />
    <parent
      link="RL_hip_Link" />
    <child
      link="RL_thigh_Link" />
    <axis
      xyz="0 -1 0" />
    <limit
      lower="-4.1538"
      upper="1.012"
      effort="120"
      velocity="8.72" />
  </joint>
  <link
    name="RL_calf_Link">
    <inertial>
      <origin
        xyz="0.01548 5.1235E-08 -0.16117"
        rpy="0 0 0" />
      <mass
        value="1.2" />
      <inertia
        ixx="0.017699"
        ixy="2.717E-10"
        ixz="-0.0011852"
        iyy="0.018059"
        iyz="-6.8945E-09"
        izz="0.0006172" />
    </inertial>
    <visual>
      <origin
        xyz="0 0 0"
        rpy="0 0 0" />
      <geometry>
        <mesh
          filename="../meshes/RL_calf_Link.STL" />
      </geometry>
      <material
        name="">
        <color
          rgba="1 1 1 1" />
      </material>
    </visual>
    <collision>
      <origin
        xyz="0 0 0"
        rpy="0 0 0" />
      <geometry>
        <mesh
          filename="../meshes/RL_calf_Link.STL" />
      </geometry>
    </collision>
  </link>
  <joint
    name="RL_calf_Joint"
    type="revolute">
    <origin
      xyz="0 0 -0.35"
      rpy="0 0 0" />
    <parent
      link="RL_thigh_Link" />
    <child
      link="RL_calf_Link" />
    <axis
      xyz="0 -1 0" />
    <limit
      lower="0.61086"
      upper="2.7925"
      effort="120"
      velocity="8.72" />
  </joint>
  <link
    name="RL_foot_Link">
    <inertial>
      <origin
        xyz="-0.0062191 -2.4425E-15 -0.011423"
        rpy="0 0 0" />
      <mass
        value="0.2" />
      <inertia
        ixx="7.7E-05"
        ixy="2.2617E-10"
        ixz="-1.97E-05"
        iyy="9.6E-05"
        iyz="-5.7823E-10"
        izz="0.0001024" />
    </inertial>
    <visual>
      <origin
        xyz="0 0 0"
        rpy="0 0 0" />
      <geometry>
        <mesh
          filename="../meshes/RL_foot_Link.STL" />
      </geometry>
      <material
        name="">
        <color
          rgba="1 1 1 1" />
      </material>
    </visual>
    <collision>
      <origin
        xyz="0 0 0"
        rpy="0 0 0" />
      <geometry>
        <mesh
          filename="../meshes/RL_foot_Link.STL" />
      </geometry>
    </collision>
  </link>
  <joint
    name="RL_foot_Joint"
    type="fixed">
    <origin
      xyz="0 0 -0.35"
      rpy="0 0 0" />
    <parent
      link="RL_calf_Link" />
    <child
      link="RL_foot_Link" />
    <axis
      xyz="0 0 0" />
  </joint>
  <link
    name="RR_hip_Link">
    <inertial>
      <origin
        xyz="0.0064702 0.0031168 -1.8861E-09"
        rpy="0 0 0" />
      <mass
        value="2.5" />
      <inertia
        ixx="0.004546"
        ixy="-0.000365"
        ixz="-4.5559E-09"
        iyy="0.0072194"
        iyz="1.0818E-08"
        izz="0.0050078" />
    </inertial>
    <visual>
      <origin
        xyz="0 0 0"
        rpy="0 0 0" />
      <geometry>
        <mesh
          filename="../meshes/RR_hip_Link.STL" />
      </geometry>
      <material
        name="">
        <color
          rgba="1 1 1 1" />
      </material>
    </visual>
    <collision>
      <origin
        xyz="0 0 0"
        rpy="0 0 0" />
      <geometry>
        <mesh
          filename="../meshes/RR_hip_Link.STL" />
      </geometry>
    </collision>
  </link>
  <joint
    name="RR_hip_Joint"
    type="revolute">
    <origin
      xyz="-0.31 -0.08 0"
      rpy="0 0 0" />
    <parent
      link="base_link" />
    <child
      link="RR_hip_Link" />
    <axis
      xyz="-1 0 0" />
    <limit
      lower="-0.7854"
      upper="0.7854"
      effort="75"
      velocity="13.96" />
  </joint>
  <link
    name="RR_thigh_Link">
    <inertial>
      <origin
        xyz="-0.013505 0.013599 -0.077042"
        rpy="0 0 0" />
      <mass
        value="3.6" />
      <inertia
        ixx="0.047245"
        ixy="0.000678"
        ixz="0.0051024"
        iyy="0.048527"
        iyz="0.0038394"
        izz="0.0074105" />
    </inertial>
    <visual>
      <origin
        xyz="0 0 0"
        rpy="0 0 0" />
      <geometry>
        <mesh
          filename="../meshes/RR_thigh_Link.STL" />
      </geometry>
      <material
        name="">
        <color
          rgba="1 1 1 1" />
      </material>
    </visual>
    <collision>
      <origin
        xyz="0 0 0"
        rpy="0 0 0" />
      <geometry>
        <mesh
          filename="../meshes/RR_thigh_Link.STL" />
      </geometry>
    </collision>
  </link>
  <joint
    name="RR_thigh_Joint"
    type="revolute">
    <origin
      xyz="0 -0.125 0"
      rpy="0 0 0" />
    <parent
      link="RR_hip_Link" />
    <child
      link="RR_thigh_Link" />
    <axis
      xyz="0 1 0" />
    <limit
      lower="-1.012"
      upper="4.1538"
      effort="120"
      velocity="8.72" />
  </joint>
  <link
    name="RR_calf_Link">
    <inertial>
      <origin
        xyz="0.01548 5.1235E-08 -0.16117"
        rpy="0 0 0" />
      <mass
        value="1.2" />
      <inertia
        ixx="0.017699"
        ixy="2.717E-10"
        ixz="-0.0011852"
        iyy="0.018059"
        iyz="-6.8945E-09"
        izz="0.0006172" />
    </inertial>
    <visual>
      <origin
        xyz="0 0 0"
        rpy="0 0 0" />
      <geometry>
        <mesh
          filename="../meshes/RR_calf_Link.STL" />
      </geometry>
      <material
        name="">
        <color
          rgba="1 1 1 1" />
      </material>
    </visual>
    <collision>
      <origin
        xyz="0 0 0"
        rpy="0 0 0" />
      <geometry>
        <mesh
          filename="../meshes/RR_calf_Link.STL" />
      </geometry>
    </collision>
  </link>
  <joint
    name="RR_calf_Joint"
    type="revolute">
    <origin
      xyz="0 0 -0.35"
      rpy="0 0 0" />
    <parent
      link="RR_thigh_Link" />
    <child
      link="RR_calf_Link" />
    <axis
      xyz="0 -1 0" />
    <limit
      lower="0.61086"
      upper="2.7925"
      effort="120"
      velocity="8.72" />
  </joint>
  <link
    name="RR_foot_Link">
    <inertial>
      <origin
        xyz="-0.0062191 -2.498E-15 -0.011423"
        rpy="0 0 0" />
      <mass
        value="0.2" />
      <inertia
        ixx="7.7E-05"
        ixy="2.2617E-10"
        ixz="-1.97E-05"
        iyy="9.6E-05"
        iyz="-5.7823E-10"
        izz="0.0001024" />
    </inertial>
    <visual>
      <origin
        xyz="0 0 0"
        rpy="0 0 0" />
      <geometry>
        <mesh
          filename="../meshes/RR_foot_Link.STL" />
      </geometry>
      <material
        name="">
        <color
          rgba="1 1 1 1" />
      </material>
    </visual>
    <collision>
      <origin
        xyz="0 0 0"
        rpy="0 0 0" />
      <geometry>
        <mesh
          filename="../meshes/RR_foot_Link.STL" />
      </geometry>
    </collision>
  </link>
  <joint
    name="RR_foot_Joint"
    type="fixed">
    <origin
      xyz="0 0 -0.35"
      rpy="0 0 0" />
    <parent
      link="RR_calf_Link" />
    <child
      link="RR_foot_Link" />
    <axis
      xyz="0 0 0" />
  </joint>
</robot>
